Workbook
Name Slicer_Dept_Clean: #N/A
Name Slicer_Gender: #N/A

Sheet Pivot_Analysis
A1: Department's Performance
A3: Departments | B3: Total Charges | C3: Admissions | D3: Average LOS
A4: ORTHOPEDICS | B4: 57848 | C4: 3 | D4: 7
A5: PEDIATRICS | B5: 13619 | C5: 2 | D5: 1.5
A6: CARDIOLOGY | B6: 552228 | C6: 34 | D6: 5.6969697
A7: ER | B7: 246661 | C7: 51 | D7: 1.6530612
A8: NEUROLOGY | B8: 459866 | C8: 22 | D8: 7
A9: ONCOLOGY | B9: 810345 | C9: 36 | D9: 8.4285714
A10: ORTHOPEDICS | B10: 783605 | C10: 43 | D10: 7.0465116
A11: PEDIATRICS | B11: 357384 | C11: 43 | D11: 2.9069767
A12: Grand Total | B12: 3281556 | C12: 234 | D12: 5.0786026
A21: Monthly Admissions Trend
A23: Row Levels | B23: Admissions
A24: 2024 | B24: 240
A25: Jan | B25: 94
A26: Feb | B26: 72
A27: Mar | B27: 74
A28: Grand Total | B28: 240

Sheet Patient_Admissions
A1: Patient_ID | B1: Age | C1: Gender | D1: Department | E1: Admission_Date | F1: Discharge_Date | G1: Length_of_Stay | H1: Readmitted | I1: Total_Charges | J1: Dept_Clean | K1: Readmitted_Clean | L1: LOS_Calc | M1: LOS_Check | N1: Target_LOS | O1: LOS_Target_Flag
A2: 2001 | B2: 42 | C2: F | D2: er | E2: 45375 | F2: 45376 | G2: 1 | H2: Yes | I2: 3889 | J2: =UPPER((SUBSTITUTE(D2,CHAR(160)," "))) -> ER | K2: =UPPER(TRIM(H2)) -> YES | L2: =IF(OR(E2="",F2=""),"",F2-E2) -> 1 | M2: =IF(OR(G2="",L2=""),"",IF(G2=L2,"Match","Mismatch")) -> Match | N2: =_xlfn.XLOOKUP(UPPER(TRIM(SUBSTITUTE(J2,CHAR(160)," "))),Departments!A:A,Departments!C:C,"") -> 2 | O2: =IF(OR(L2="",N2=""),"",IF(L2>N2,"Above Target","Within Target")) -> Within Target
A3: 2002 | B3: 56 | C3: M | D3: Cardiology | E3: 45322 | F3: 45325 | G3: 3 | H3: No | I3: 12956 | J3: =UPPER((SUBSTITUTE(D3,CHAR(160)," "))) -> CARDIOLOGY | K3: =UPPER(TRIM(H3)) -> NO | L3: =IF(OR(E3="",F3=""),"",F3-E3) -> 3 | M3: =IF(OR(G3="",L3=""),"",IF(G3=L3,"Match","Mismatch")) -> Match | N3: =_xlfn.XLOOKUP(UPPER(TRIM(SUBSTITUTE(J3,CHAR(160)," "))),Departments!A:A,Departments!C:C,"") -> 5 | O3: =IF(OR(L3="",N3=""),"",IF(L3>N3,"Above Target","Within Target")) -> Within Target
A4: 2003 | B4: 8 | C4: M | D4: Cardiology | E4: 45320 | F4: 45322 | G4: 2 | H4: No | I4: 11137 | J4: =UPPER((SUBSTITUTE(D4,CHAR(160)," "))) -> CARDIOLOGY | K4: =UPPER(TRIM(H4)) -> NO | L4: =IF(OR(E4="",F4=""),"",F4-E4) -> 2 | M4: =IF(OR(G4="",L4=""),"",IF(G4=L4,"Match","Mismatch")) -> Match | N4: =_xlfn.XLOOKUP(UPPER(TRIM(SUBSTITUTE(J4,CHAR(160)," "))),Departments!A:A,Departments!C:C,"") -> 5 | O4: =IF(OR(L4="",N4=""),"",IF(L4>N4,"Above Target","Within Target")) -> Within Target
A5: 2004 | B5: 88 | C5: F | D5: Cardiology | E5: 45366 | F5: 45371 | G5: 5 | H5: No | I5: 19763 | J5: =UPPER((SUBSTITUTE(D5,CHAR(160)," "))) -> CARDIOLOGY | K5: =UPPER(TRIM(H5)) -> NO | L5: =IF(OR(E5="",F5=""),"",F5-E5) -> 5 | M5: =IF(OR(G5="",L5=""),"",IF(G5=L5,"Match","Mismatch")) -> Match | N5: =_xlfn.XLOOKUP(UPPER(TRIM(SUBSTITUTE(J5,CHAR(160)," "))),Departments!A:A,Departments!C:C,"") -> 5 | O5: =IF(OR(L5="",N5=""),"",IF(L5>N5,"Above Target","Within Target")) -> Within Target
A6: 2005 | B6: 55 | C6: M | D6: ER | E6: 45366 | F6: 45368 | G6: 2 | H6: No | I6: 6142 | J6: =UPPER((SUBSTITUTE(D6,CHAR(160)," "))) -> ER | K6: =UPPER(TRIM(H6)) -> NO | L6: =IF(OR(E6="",F6=""),"",F6-E6) -> 2 | M6: =IF(OR(G6="",L6=""),"",IF(G6=L6,"Match","Mismatch")) -> Match | N6: =_xlfn.XLOOKUP(UPPER(TRIM(SUBSTITUTE(J6,CHAR(160)," "))),Departments!A:A,Departments!C:C,"") -> 2 | O6: =IF(OR(L6="",N6=""),"",IF(L6>N6,"Above Target","Within Target")) -> Within Target
A7: 2006 | B7: 64 | C7: M | D7: Pediatrics | E7: 45349 | F7: 45352 | G7: 3 | H7: No | I7: 6588 | J7: =UPPER((SUBSTITUTE(D7,CHAR(160)," "))) -> PEDIATRICS | K7: =UPPER(TRIM(H7)) -> NO | L7: =IF(OR(E7="",F7=""),"",F7-E7) -> 3 | M7: =IF(OR(G7="",L7=""),"",IF(G7=L7,"Match","Mismatch")) -> Match | N7: =_xlfn.XLOOKUP(UPPER(TRIM(SUBSTITUTE(J7,CHAR(160)," "))),Departments!A:A,Departments!C:C,"") -> 3 | O7: =IF(OR(L7="",N7=""),"",IF(L7>N7,"Above Target","Within Target")) -> Within Target
A8: 2007 | B8: 54 | C8: F | D8: Pediatrics | E8: 45301 | F8: 45306 | G8: 5 | H8: No | I8: 11606 | J8: =UPPER((SUBSTITUTE(D8,CHAR(160)," "))) -> PEDIATRICS | K8: =UPPER(TRIM(H8)) -> NO | L8: =IF(OR(E8="",F8=""),"",F8-E8) -> 5 | M8: =IF(OR(G8="",L8=""),"",IF(G8=L8,"Match","Mismatch")) -> Match | N8: =_xlfn.XLOOKUP(UPPER(TRIM(SUBSTITUTE(J8,CHAR(160)," "))),Departments!A:A,Departments!C:C,"") -> 3 | O8: =IF(OR(L8="",N8=""),"",IF(L8>N8,"Above Target","Within Target")) -> Above Target
A9: 2008 | B9: 12 | C9: M | D9: ER | E9: 45381 | F9: 45384 | G9: 3 | H9: Yes | I9: 7627 | J9: =UPPER((SUBSTITUTE(D9,CHAR(160)," "))) -> ER | K9: =UPPER(TRIM(H9)) -> YES | L9: =IF(OR(E9="",F9=""),"",F9-E9) -> 3 | M9: =IF(OR(G9="",L9=""),"",IF(G9=L9,"Match","Mismatch")) -> Match | N9: =_xlfn.XLOOKUP(UPPER(TRIM(SUBSTITUTE(J9,CHAR(160)," "))),Departments!A:A,Departments!C:C,"") -> 2 | O9: =IF(OR(L9="",N9=""),"",IF(L9>N9,"Above Target","Within Target")) -> Above Target
A10: 2009 | B10: 86 | C10: M | D10: Cardiology | E10: 45351 | F10: 45358 | G10: 7 | H10: Yes | I10: 17184 | J10: =UPPER((SUBSTITUTE(D10,CHAR(160)," "))) -> CARDIOLOGY | K10: =UPPER(TRIM(H10)) -> YES | L10: =IF(OR(E10="",F10=""),"",F10-E10) -> 7 | M10: =IF(OR(G10="",L10=""),"",IF(G10=L10,"Match","Mismatch")) -> Match | N10: =_xlfn.XLOOKUP(UPPER(TRIM(SUBSTITUTE(J10,CHAR(160)," "))),Departments!A:A,Departments!C:C,"") -> 5 | O10: =IF(OR(L10="",N10=""),"",IF(L10>N10,"Above Target","Within Target")) -> Above Target
A11: 2010 | B11: 51 | C11: M | D11: Cardiology | E11: 45313 | F11: 45322 | G11: 9 | H11: No | I11: 23230 | J11: =UPPER((SUBSTITUTE(D11,CHAR(160)," "))) -> CARDIOLOGY | K11: =UPPER(TRIM(H11)) -> NO | L11: =IF(OR(E11="",F11=""),"",F11-E11) -> 9 | M11: =IF(OR(G11="",L11=""),"",IF(G11=L11,"Match","Mismatch")) -> Match | N11: =_xlfn.XLOOKUP(UPPER(TRIM(SUBSTITUTE(J11,CHAR(160)," "))),Departments!A:A,Departments!C:C,"") -> 5 | O11: =IF(OR(L11="",N11=""),"",IF(L11>N11,"Above Target","Within Target")) -> Above Target
A12: 2011 | B12: 46 | C12: M | D12: Orthopedics | E12: 45311 | F12: 45314 | G12: 3 | H12: No | I12: 12673 | J12: =UPPER((SUBSTITUTE(D12,CHAR(160)," "))) -> ORTHOPEDICS | K12: =UPPER(TRIM(H12)) -> NO | L12: =IF(OR(E12="",F12=""),"",F12-E12) -> 3 | M12: =IF(OR(G12="",L12=""),"",IF(G12=L12,"Match","Mismatch")) -> Match | N12: =_xlfn.XLOOKUP(UPPER(TRIM(SUBSTITUTE(J12,CHAR(160)," "))),Departments!A:A,Departments!C:C,"") -> 6 | O12: =IF(OR(L12="",N12=""),"",IF(L12>N12,"Above Target","Within Target")) -> Within Target
A13: 2012 | B13: 1 | C13: F | D13: ER | E13: 45360 | F13: 45361 | G13: 1 | H13: No | I13: 5203 | J13: =UPPER((SUBSTITUTE(D13,CHAR(160)," "))) -> ER | K13: =UPPER(TRIM(H13)) -> NO | L13: =IF(OR(E13="",F13=""),"",F13-E13) -> 1 | M13: =IF(OR(G13="",L13=""),"",IF(G13=L13,"Match","Mismatch")) -> Match | N13: =_xlfn.XLOOKUP(UPPER(TRIM(SUBSTITUTE(J13,CHAR(160)," "))),Departments!A:A,Departments!C:C,"") -> 2 | O13: =IF(OR(L13="",N13=""),"",IF(L13>N13,"Above Target","Within Target")) -> Within Target
... A19: 2018 | B19: 47 | C19: F | D19: Neurology | E19: 45320 | F19: 45331 | G19: 11 | H19: No | I19: 29594 | J19: =UPPER((SUBSTITUTE(D19,CHAR(160)," "))) -> NEUROLOGY | K19: =UPPER(TRIM(H19)) -> NO | L19: =IF(OR(E19="",F19=""),"",F19-E19) -> 11 | M19: =IF(OR(G19="",L19=""),"",IF(G19=L19,"Match","Mismatch")) -> Match | N19: =_xlfn.XLOOKUP(UPPER(TRIM(SUBSTITUTE(J19,CHAR(160)," "))),Departments!A:A,Departments!C:C,"") -> 7 | O19: =IF(OR(L19="",N19=""),"",IF(L19>N19,"Above Target","Within Target")) -> Above Target
A20: 2019 | B20: 25 | C20: F | D20: ER | E20: 45321 | G20: 1 | H20: No | J20: =UPPER((SUBSTITUTE(D20,CHAR(160)," "))) -> ER | K20: =UPPER(TRIM(H20)) -> NO | L20: =IF(OR(E20="",F20=""),"",F20-E20) | M20: =IF(OR(G20="",L20=""),"",IF(G20=L20,"Match","Mismatch")) | N20: =_xlfn.XLOOKUP(UPPER(TRIM(SUBSTITUTE(J20,CHAR(160)," "))),Departments!A:A,Departments!C:C,"") -> 2 | O20: =IF(OR(L20="",N20=""),"",IF(L20>N20,"Above Target","Within Target"))
A21: 2020 | B21: 89 | C21: M | D21: ER | E21: 45336 | F21: 45337 | G21: 1 | H21: Yes | I21: 3273 | J21: =UPPER((SUBSTITUTE(D21,CHAR(160)," "))) -> ER | K21: =UPPER(TRIM(H21)) -> YES | L21: =IF(OR(E21="",F21=""),"",F21-E21) -> 1 | M21: =IF(OR(G21="",L21=""),"",IF(G21=L21,"Match","Mismatch")) -> Match | N21: =_xlfn.XLOOKUP(UPPER(TRIM(SUBSTITUTE(J21,CHAR(160)," "))),Departments!A:A,Departments!C:C,"") -> 2 | O21: =IF(OR(L21="",N21=""),"",IF(L21>N21,"Above Target","Within Target")) -> Within Target
A22: 2021 | B22: 79 | C22: F | D22: ER | E22: 45375 | F22: 45376 | G22: 1 | H22: No | I22: 4482 | J22: =UPPER((SUBSTITUTE(D22,CHAR(160)," "))) -> ER | K22: =UPPER(TRIM(H22)) -> NO | L22: =IF(OR(E22="",F22=""),"",F22-E22) -> 1 | M22: =IF(OR(G22="",L22=""),"",IF(G22=L22,"Match","Mismatch")) -> Match | N22: =_xlfn.XLOOKUP(UPPER(TRIM(SUBSTITUTE(J22,CHAR(160)," "))),Departments!A:A,Departments!C:C,"") -> 2 | O22: =IF(OR(L22="",N22=""),"",IF(L22>N22,"Above Target","Within Target")) -> Within Target
A23: 2022 | B23: 62 | C23: F | D23: ER | E23: 45373 | F23: 45374 | G23: 1 | H23: Yes | I23: 4358 | J23: =UPPER((SUBSTITUTE(D23,CHAR(160)," "))) -> ER | K23: =UPPER(TRIM(H23)) -> YES | L23: =IF(OR(E23="",F23=""),"",F23-E23) -> 1 | M23: =IF(OR(G23="",L23=""),"",IF(G23=L23,"Match","Mismatch")) -> Match | N23: =_xlfn.XLOOKUP(UPPER(TRIM(SUBSTITUTE(J23,CHAR(160)," "))),Departments!A:A,Departments!C:C,"") -> 2 | O23: =IF(OR(L23="",N23=""),"",IF(L23>N23,"Above Target","Within Target")) -> Within Target
A24: 2023 | B24: 17 | C24: F | D24: Orthopedics | E24: 45367 | F24: 45376 | G24: 9 | H24: No | I24: 19243 | J24: =UPPER((SUBSTITUTE(D24,CHAR(160)," "))) -> ORTHOPEDICS | K24: =UPPER(TRIM(H24)) -> NO | L24: =IF(OR(E24="",F24=""),"",F24-E24) -> 9 | M24: =IF(OR(G24="",L24=""),"",IF(G24=L24,"Match","Mismatch")) -> Match | N24: =_xlfn.XLOOKUP(UPPER(TRIM(SUBSTITUTE(J24,CHAR(160)," "))),Departments!A:A,Departments!C:C,"") -> 6 | O24: =IF(OR(L24="",N24=""),"",IF(L24>N24,"Above Target","Within Target")) -> Above Target
A25: 2024 | B25: 71 | C25: F | D25: cardiology | E25: 45293 | F25: 45296 | G25: 3 | H25: No | I25: 12643 | J25: =UPPER((SUBSTITUTE(D25,CHAR(160)," "))) -> CARDIOLOGY | K25: =UPPER(TRIM(H25)) -> NO | L25: =IF(OR(E25="",F25=""),"",F25-E25) -> 3 | M25: =IF(OR(G25="",L25=""),"",IF(G25=L25,"Match","Mismatch")) -> Match | N25: =_xlfn.XLOOKUP(UPPER(TRIM(SUBSTITUTE(J25,CHAR(160)," "))),Departments!A:A,Departments!C:C,"") -> 5 | O25: =IF(OR(L25="",N25=""),"",IF(L25>N25,"Above Target","Within Target")) -> Within Target
A26: 2025 | B26: 28 | C26: M | D26: Oncology | E26: 45322 | F26: 45336 | G26: 14 | H26: No | I26: 29848 | J26: =UPPER((SUBSTITUTE(D26,CHAR(160)," "))) -> ONCOLOGY | K26: =UPPER(TRIM(H26)) -> NO | L26: =IF(OR(E26="",F26=""),"",F26-E26) -> 14 | M26: =IF(OR(G26="",L26=""),"",IF(G26=L26,"Match","Mismatch")) -> Match | N26: =_xlfn.XLOOKUP(UPPER(TRIM(SUBSTITUTE(J26,CHAR(160)," "))),Departments!A:A,Departments!C:C,"") -> 6 | O26: =IF(OR(L26="",N26=""),"",IF(L26>N26,"Above Target","Within Target")) -> Above Target
A27: 2026 | B27: 59 | C27: M | D27: Oncology | E27: 45308 | F27: 45318 | G27: 10 | H27: Yes | I27: 28188 | J27: =UPPER((SUBSTITUTE(D27,CHAR(160)," "))) -> ONCOLOGY | K27: =UPPER(TRIM(H27)) -> YES | L27: =IF(OR(E27="",F27=""),"",F27-E27) -> 10 | M27: =IF(OR(G27="",L27=""),"",IF(G27=L27,"Match","Mismatch")) -> Match | N27: =_xlfn.XLOOKUP(UPPER(TRIM(SUBSTITUTE(J27,CHAR(160)," "))),Departments!A:A,Departments!C:C,"") -> 6 | O27: =IF(OR(L27="",N27=""),"",IF(L27>N27,"Above Target","Within Target")) -> Above Target
A28: 2027 | B28: 20 | C28: F | D28: Orthopedics | E28: 45352 | F28: 45363 | G28: 11 | H28: No | I28: 29755 | J28: =UPPER((SUBSTITUTE(D28,CHAR(160)," "))) -> ORTHOPEDICS | K28: =UPPER(TRIM(H28)) -> NO | L28: =IF(OR(E28="",F28=""),"",F28-E28) -> 11 | M28: =IF(OR(G28="",L28=""),"",IF(G28=L28,"Match","Mismatch")) -> Match | N28: =_xlfn.XLOOKUP(UPPER(TRIM(SUBSTITUTE(J28,CHAR(160)," "))),Departments!A:A,Departments!C:C,"") -> 6 | O28: =IF(OR(L28="",N28=""),"",IF(L28>N28,"Above Target","Within Target")) -> Above Target
A29: 2028 | B29: 14 | C29: F | D29: Orthopedics | E29: 45316 | G29: 6 | H29: Yes | I29: 14839 | J29: =UPPER((SUBSTITUTE(D29,CHAR(160)," "))) -> ORTHOPEDICS | K29: =UPPER(TRIM(H29)) -> YES | L29: =IF(OR(E29="",F29=""),"",F29-E29) | M29: =IF(OR(G29="",L29=""),"",IF(G29=L29,"Match","Mismatch")) | N29: =_xlfn.XLOOKUP(UPPER(TRIM(SUBSTITUTE(J29,CHAR(160)," "))),Departments!A:A,Departments!C:C,"") -> 6 | O29: =IF(OR(L29="",N29=""),"",IF(L29>N29,"Above Target","Within Target"))
A30: 2029 | B30: 42 | C30: F | D30: Pediatrics | E30: 45327 | F30: 45331 | G30: 4 | H30: No | I30: 11755 | J30: =UPPER((SUBSTITUTE(D30,CHAR(160)," "))) -> PEDIATRICS | K30: =UPPER(TRIM(H30)) -> NO | L30: =IF(OR(E30="",F30=""),"",F30-E30) -> 4 | M30: =IF(OR(G30="",L30=""),"",IF(G30=L30,"Match","Mismatch")) -> Match | N30: =_xlfn.XLOOKUP(UPPER(TRIM(SUBSTITUTE(J30,CHAR(160)," "))),Departments!A:A,Departments!C:C,"") -> 3 | O30: =IF(OR(L30="",N30=""),"",IF(L30>N30,"Above Target","Within Target")) -> Above Target
A31: 2030 | B31: 34 | C31: F | D31: ER | E31: 45309 | F31: 45311 | G31: 2 | H31: Yes | I31: 5957 | J31: =UPPER((SUBSTITUTE(D31,CHAR(160)," "))) -> ER | K31: =UPPER(TRIM(H31)) -> YES | L31: =IF(OR(E31="",F31=""),"",F31-E31) -> 2 | M31: =IF(OR(G31="",L31=""),"",IF(G31=L31,"Match","Mismatch")) -> Match | N31: =_xlfn.XLOOKUP(UPPER(TRIM(SUBSTITUTE(J31,CHAR(160)," "))),Departments!A:A,Departments!C:C,"") -> 2 | O31: =IF(OR(L31="",N31=""),"",IF(L31>N31,"Above Target","Within Target")) -> Within Target
A32: 2031 | B32: 16 | C32: F | D32: Pediatrics | E32: 45374 | F32: 45377 | G32: 3 | H32: No | I32: 8724 | J32: =UPPER((SUBSTITUTE(D32,CHAR(160)," "))) -> PEDIATRICS | K32: =UPPER(TRIM(H32)) -> NO | L32: =IF(OR(E32="",F32=""),"",F32-E32) -> 3 | M32: =IF(OR(G32="",L32=""),"",IF(G32=L32,"Match","Mismatch")) -> Match | N32: =_xlfn.XLOOKUP(UPPER(TRIM(SUBSTITUTE(J32,CHAR(160)," "))),Departments!A:A,Departments!C:C,"") -> 3 | O32: =IF(OR(L32="",N32=""),"",IF(L32>N32,"Above Target","Within Target")) -> Within Target
A33: 2032 | B33: 21 | C33: F | D33: Orthopedics | E33: 45347 | F33: 45357 | G33: 10 | H33: No | I33: 25220 | J33: =UPPER((SUBSTITUTE(D33,CHAR(160)," "))) -> ORTHOPEDICS | K33: =UPPER(TRIM(H33)) -> NO | L33: =IF(OR(E33="",F33=""),"",F33-E33) -> 10 | M33: =IF(OR(G33="",L33=""),"",IF(G33=L33,"Match","Mismatch")) -> Match | N33: =_xlfn.XLOOKUP(UPPER(TRIM(SUBSTITUTE(J33,CHAR(160)," "))),Departments!A:A,Departments!C:C,"") -> 6 | O33: =IF(OR(L33="",N33=""),"",IF(L33>N33,"Above Target","Within Target")) -> Above Target
A34: 2033 | B34: 59 | C34: M | D34: Pediatrics | E34: 45294 | F34: 45298 | G34: 4 | H34: No | I34: 12513 | J34: =UPPER((SUBSTITUTE(D34,CHAR(160)," "))) -> PEDIATRICS | K34: =UPPER(TRIM(H34)) -> NO | L34: =IF(OR(E34="",F34=""),"",F34-E34) -> 4 | M34: =IF(OR(G34="",L34=""),"",IF(G34=L34,"Match","Mismatch")) -> Match | N34: =_xlfn.XLOOKUP(UPPER(TRIM(SUBSTITUTE(J34,CHAR(160)," "))),Departments!A:A,Departments!C:C,"") -> 3 | O34: =IF(OR(L34="",N34=""),"",IF(L34>N34,"Above Target","Within Target")) -> Above Target
A35: 2034 | B35: 14 | C35: F | D35: Neurology | E35: 45326 | F35: 45329 | G35: 3 | H35: No | I35: 12066 | J35: =UPPER((SUBSTITUTE(D35,CHAR(160)," "))) -> NEUROLOGY | K35: =UPPER(TRIM(H35)) -> NO | L35: =IF(OR(E35="",F35=""),"",F35-E35) -> 3 | M35: =IF(OR(G35="",L35=""),"",IF(G35=L35,"Match","Mismatch")) -> Match | N35: =_xlfn.XLOOKUP(UPPER(TRIM(SUBSTITUTE(J35,CHAR(160)," "))),Departments!A:A,Departments!C:C,"") -> 7 | O35: =IF(OR(L35="",N35=""),"",IF(L35>N35,"Above Target","Within Target")) -> Within Target
A36: 2035 | B36: 34 | C36: M | D36: Orthopedics | E36: 45360 | F36: 45370 | G36: 10 | H36: No | I36: 23073 | J36: =UPPER((SUBSTITUTE(D36,CHAR(160)," "))) -> ORTHOPEDICS | K36: =UPPER(TRIM(H36)) -> NO | L36: =IF(OR(E36="",F36=""),"",F36-E36) -> 10 | M36: =IF(OR(G36="",L36=""),"",IF(G36=L36,"Match","Mismatch")) -> Match | N36: =_xlfn.XLOOKUP(UPPER(TRIM(SUBSTITUTE(J36,CHAR(160)," "))),Departments!A:A,Departments!C:C,"") -> 6 | O36: =IF(OR(L36="",N36=""),"",IF(L36>N36,"Above Target","Within Target")) -> Above Target
A37: 2036 | B37: 35 | C37: F | D37: Pediatrics | E37: 45303 | F37: 45306 | H37: Yes | I37: 7401 | J37: =UPPER((SUBSTITUTE(D37,CHAR(160)," "))) -> PEDIATRICS | K37: =UPPER(TRIM(H37)) -> YES | L37: =IF(OR(E37="",F37=""),"",F37-E37) -> 3 | M37: =IF(OR(G37="",L37=""),"",IF(G37=L37,"Match","Mismatch")) | N37: =_xlfn.XLOOKUP(UPPER(TRIM(SUBSTITUTE(J37,CHAR(160)," "))),Departments!A:A,Departments!C:C,"") -> 3 | O37: =IF(OR(L37="",N37=""),"",IF(L37>N37,"Above Target","Within Target")) -> Within Target
A38: 2037 | B38: 54 | C38: M | D38: Oncology | E38: 45308 | F38: 45310 | G38: 2 | H38: No | I38: 13397 | J38: =UPPER((SUBSTITUTE(D38,CHAR(160)," "))) -> ONCOLOGY | K38: =UPPER(TRIM(H38)) -> NO | L38: =IF(OR(E38="",F38=""),"",F38-E38) -> 2 | M38: =IF(OR(G38="",L38=""),"",IF(G38=L38,"Match","Mismatch")) -> Match | N38: =_xlfn.XLOOKUP(UPPER(TRIM(SUBSTITUTE(J38,CHAR(160)," "))),Departments!A:A,Departments!C:C,"") -> 6 | O38: =IF(OR(L38="",N38=""),"",IF(L38>N38,"Above Target","Within Target")) -> Within Target
A39: 2038 | B39: 40 | C39: M | D39: oncology | E39: 45318 | G39: 6 | H39: No | I39: 16838 | J39: =UPPER((SUBSTITUTE(D39,CHAR(160)," "))) -> ONCOLOGY | K39: =UPPER(TRIM(H39)) -> NO | L39: =IF(OR(E39="",F39=""),"",F39-E39) | M39: =IF(OR(G39="",L39=""),"",IF(G39=L39,"Match","Mismatch")) | N39: =_xlfn.XLOOKUP(UPPER(TRIM(SUBSTITUTE(J39,CHAR(160)," "))),Departments!A:A,Departments!C:C,"") -> 6 | O39: =IF(OR(L39="",N39=""),"",IF(L39>N39,"Above Target","Within Target"))
A40: 2039 | B40: 65 | C40: F | D40: Oncology | E40: 45352 | F40: 45357 | G40: 5 | H40: No | I40: 15633 | J40: =UPPER((SUBSTITUTE(D40,CHAR(160)," "))) -> ONCOLOGY | K40: =UPPER(TRIM(H40)) -> NO | L40: =IF(OR(E40="",F40=""),"",F40-E40) -> 5 | M40: =IF(OR(G40="",L40=""),"",IF(G40=L40,"Match","Mismatch")) -> Match | N40: =_xlfn.XLOOKUP(UPPER(TRIM(SUBSTITUTE(J40,CHAR(160)," "))),Departments!A:A,Departments!C:C,"") -> 6 | O40: =IF(OR(L40="",N40=""),"",IF(L40>N40,"Above Target","Within Target")) -> Within Target
A41: 2040 | B41: 51 | C41: M | D41: pediatrics | E41: 45319 | F41: 45321 | G41: 2 | H41: No | I41: 6400 | J41: =UPPER((SUBSTITUTE(D41,CHAR(160)," "))) -> PEDIATRICS | K41: =UPPER(TRIM(H41)) -> NO | L41: =IF(OR(E41="",F41=""),"",F41-E41) -> 2 | M41: =IF(OR(G41="",L41=""),"",IF(G41=L41,"Match","Mismatch")) -> Match | N41: =_xlfn.XLOOKUP(UPPER(TRIM(SUBSTITUTE(J41,CHAR(160)," "))),Departments!A:A,Departments!C:C,"") -> 3 | O41: =IF(OR(L41="",N41=""),"",IF(L41>N41,"Above Target","Within Target")) -> Within Target
A42: 2041 | B42: 81 | C42: M | D42: ER | E42: 45312 | F42: 45313 | G42: 1 | H42: Yes | I42: 5162 | J42: =UPPER((SUBSTITUTE(D42,CHAR(160)," "))) -> ER | K42: =UPPER(TRIM(H42)) -> YES | L42: =IF(OR(E42="",F42=""),"",F42-E42) -> 1 | M42: =IF(OR(G42="",L42=""),"",IF(G42=L42,"Match","Mismatch")) -> Match | N42: =_xlfn.XLOOKUP(UPPER(TRIM(SUBSTITUTE(J42,CHAR(160)," "))),Departments!A:A,Departments!C:C,"") -> 2 | O42: =IF(OR(L42="",N42=""),"",IF(L42>N42,"Above Target","Within Target")) -> Within Target
A43: 2042 | B43: 6 | C43: M | D43: Orthopedics | E43: 45312 | F43: 45318 | G43: 6 | H43: No | I43: 16579 | J43: =UPPER((SUBSTITUTE(D43,CHAR(160)," "))) -> ORTHOPEDICS | K43: =UPPER(TRIM(H43)) -> NO | L43: =IF(OR(E43="",F43=""),"",F43-E43) -> 6 | M43: =IF(OR(G43="",L43=""),"",IF(G43=L43,"Match","Mismatch")) -> Match | N43: =_xlfn.XLOOKUP(UPPER(TRIM(SUBSTITUTE(J43,CHAR(160)," "))),Departments!A:A,Departments!C:C,"") -> 6 | O43: =IF(OR(L43="",N43=""),"",IF(L43>N43,"Above Target","Within Target")) -> Within Target
A44: 2043 | B44: 40 | C44: F | D44: Neurology | E44: 45315 | F44: 45318 | G44: 3 | H44: No | I44: 11885 | J44: =UPPER((SUBSTITUTE(D44,CHAR(160)," "))) -> NEUROLOGY | K44: =UPPER(TRIM(H44)) -> NO | L44: =IF(OR(E44="",F44=""),"",F44-E44) -> 3 | M44: =IF(OR(G44="",L44=""),"",IF(G44=L44,"Match","Mismatch")) -> Match | N44: =_xlfn.XLOOKUP(UPPER(TRIM(SUBSTITUTE(J44,CHAR(160)," "))),Departments!A:A,Departments!C:C,"") -> 7 | O44: =IF(OR(L44="",N44=""),"",IF(L44>N44,"Above Target","Within Target")) -> Within Target
A45: 2044 | B45: 12 | C45: M | D45: Cardiology | E45: 45310 | F45: 45318 | G45: 8 | H45: No | I45: 21894 | J45: =UPPER((SUBSTITUTE(D45,CHAR(160)," "))) -> CARDIOLOGY | K45: =UPPER(TRIM(H45)) -> NO | L45: =IF(OR(E45="",F45=""),"",F45-E45) -> 8 | M45: =IF(OR(G45="",L45=""),"",IF(G45=L45,"Match","Mismatch")) -> Match | N45: =_xlfn.XLOOKUP(UPPER(TRIM(SUBSTITUTE(J45,CHAR(160)," "))),Departments!A:A,Departments!C:C,"") -> 5 | O45: =IF(OR(L45="",N45=""),"",IF(L45>N45,"Above Target","Within Target")) -> Above Target
...

Sheet Dashboard
B1: Healthcare Admissions Performance Dashboard
B2: Total Admissions | D2: Avg Length of Stay | F2: Readmission Rate | H2: Total Charges | J2: % Above Target LOS
B3: =COUNTA(Patient_Admissions!A2:A2241) -> 240 | D3: =AVERAGE(Patient_Admissions!L2:L2241) -> 5.106383 | F3: =COUNTIF(Patient_Admissions!K2:K2241,"YES") / COUNTA(Patient_Admissions!A2:A2241) -> 0.22083333 | H3: =SUM(Patient_Admissions!I2:I2241) -> 3395663 | J3: =COUNTIF(Patient_Admissions!O2:O2241,"Above Target")/COUNTIF(Patient_Admissions!O2:O2241,"<>") -> 0.4

Sheet Departments
A1: Department | B1: Dept_Manager | C1: Avg_Target_LOS
A2: Cardiology | B2: Dr. Smith | C2: 5
A3: Orthopedics | B3: Dr. Lee | C3: 6
A4: Neurology | B4: Dr. Patel | C4: 7
A5: ER | B5: Dr. Gomez | C5: 2
A6: Oncology | B6: Dr. Nguyen | C6: 6
A7: Pediatrics | B7: Dr. Johnson | C7: 3

Sheet Portfolio_Instructions
A1: This workbook contains SYNTHETIC (fake) healthcare admissions data for portfolio practice.
A2: Goal: Build pivot tables, formulas (SUMIFS/COUNTIFS/AVERAGEIFS), and a dashboard.
A3: Data quality: Some rows have missing Total_Charges, Discharge_Date, or Length_of_Stay.
A4: Cleaning practice: Department field includes inconsistent casing and extra spaces.
A6: Suggested portfolio outputs:
A7: 1) KPI cards: Total Admissions, Avg LOS, Readmission Rate, Total Charges (exclude blanks).
A8: 2) Pivot: Department -> Avg LOS, Total Charges, Count of Patients; add slicers.
A9: 3) Chart: Avg LOS by Department; Trend: Admissions per month.
A10: 4) Insights: 3 findings + 3 recommendations (healthcare operations angle).
